Workbook

Sheet CorST
A1: Слово | B1: Частота-CorST | C1: IPM-CorST | D1: Ранг-CorST | E1: Номер строки, на которой слово стоит в RLC | F1: IPM-RLC
A2: в | B2: 35889 | C2: 11520.564 | D2: 1 | E2: =MATCH(A2 , RLC!A:A , 0) -> 3 | F2: {=INDEX(RLC!C:C ,E2 , )} -> 37993.234
A3: и | B3: 31435 | C3: 10090.806 | D3: =D2 + 1 -> 2 | E3: =MATCH(A3 , RLC!A:A , 0) -> 2 | F3: {=INDEX(RLC!C:C ,E3 , )} -> 38334.702
A4: на | B4: 13212 | C4: 4241.1239 | D4: =D3 + 1 -> 3 | E4: =MATCH(A4 , RLC!A:A , 0) -> 5 | F4: {=INDEX(RLC!C:C ,E4 , )} -> 13265.412
A5: не | B5: 11811 | C5: 3791.3953 | D5: =D4 + 1 -> 4 | E5: =MATCH(A5 , RLC!A:A , 0) -> 6 | F5: {=INDEX(RLC!C:C ,E5 , )} -> 12860.168
A6: с | B6: 11363 | C6: 3647.5848 | D6: =D5 + 1 -> 5 | E6: =MATCH(A6 , RLC!A:A , 0) -> 8 | F6: {=INDEX(RLC!C:C ,E6 , )} -> 9178.432
A7: что | B7: 10265 | C7: 3295.1208 | D7: =D6 + 1 -> 6 | E7: =MATCH(A7 , RLC!A:A , 0) -> 4 | F7: {=INDEX(RLC!C:C ,E7 , )} -> 16305.402
A8: как | B8: 7396 | C8: 2374.1562 | D8: =D7 + 1 -> 7 | E8: =MATCH(A8 , RLC!A:A , 0) -> 9 | F8: {=INDEX(RLC!C:C ,E8 , )} -> 8273.6097
A9: к | B9: 6790 | C9: 2179.6269 | D9: =D8 + 1 -> 8 | E9: =MATCH(A9 , RLC!A:A , 0) -> 15 | F9: {=INDEX(RLC!C:C ,E9 , )} -> 4742.0127
A10: а | B10: 5924 | C10: 1901.6362 | D10: =D9 + 1 -> 9 | E10: =MATCH(A10 , RLC!A:A , 0) -> 20 | F10: {=INDEX(RLC!C:C ,E10 , )} -> 3449.2197
A11: для | B11: 5652 | C11: 1814.3227 | D11: =D10 + 1 -> 10 | E11: =MATCH(A11 , RLC!A:A , 0) -> 14 | F11: {=INDEX(RLC!C:C ,E11 , )} -> 5009.0748
A12: по | B12: 5634 | C12: 1808.5447 | D12: =D11 + 1 -> 11 | E12: =MATCH(A12 , RLC!A:A , 0) -> 16 | F12: {=INDEX(RLC!C:C ,E12 , )} -> 4641.034
A13: о | B13: 4912 | C13: 1576.7787 | D13: =D12 + 1 -> 12 | E13: =MATCH(A13 , RLC!A:A , 0) -> 13 | F13: {=INDEX(RLC!C:C ,E13 , )} -> 5022.3615
A14: из | B14: 4365 | C14: 1401.1887 | D14: =D13 + 1 -> 13 | E14: =MATCH(A14 , RLC!A:A , 0) -> 17 | F14: {=INDEX(RLC!C:C ,E14 , )} -> 4432.4333
... A1349: форм | B1349: 92 | C1349: 29.532501 | D1349: =D1348 + 1 -> 1348 | E1349: =MATCH(A1349 , RLC!A:A , 0) -> 5289 | F1349: {=INDEX(RLC!C:C ,E1349 , )} -> 21.258673
A1350: школе | B1350: 92 | C1350: 29.532501 | D1350: =D1349 + 1 -> 1349 | E1350: =MATCH(A1350 , RLC!A:A , 0) -> 404 | F1350: {=INDEX(RLC!C:C ,E1350 , )} -> 259.09008 | G1350: =C1350>E1350 -> FALSE
A1351: элементов | B1351: 92 | C1351: 29.532501 | D1351: =D1350 + 1 -> 1350 | E1351: =MATCH(A1351 , RLC!A:A , 0) -> 4112 | F1351: {=INDEX(RLC!C:C ,E1351 , )} -> 27.902008
A1352: этими | B1352: 92 | C1352: 29.532501 | D1352: =D1351 + 1 -> 1351 | E1352: =MATCH(A1352 , RLC!A:A , 0) -> 1492 | F1352: {=INDEX(RLC!C:C ,E1352 , )} -> 77.062689
A1353: артикля | B1353: 91 | C1353: 29.211495 | D1353: =D1352 + 1 -> 1352 | E1353: =MATCH(A1353 , RLC!A:A , 0) -> #N/A | F1353: {=INDEX(RLC!C:C ,E1353 , )} -> #N/A
A1354: всему | B1354: 91 | C1354: 29.211495 | D1354: =D1353 + 1 -> 1353 | E1354: =MATCH(A1354 , RLC!A:A , 0) -> 741 | F1354: {=INDEX(RLC!C:C ,E1354 , )} -> 144.82471
A1355: выполнения | B1355: 91 | C1355: 29.211495 | D1355: =D1354 + 1 -> 1354 | E1355: =MATCH(A1355 , RLC!A:A , 0) -> #N/A | F1355: {=INDEX(RLC!C:C ,E1355 , )} -> #N/A
A1356: достоевский | B1356: 91 | C1356: 29.211495 | D1356: =D1355 + 1 -> 1355 | E1356: =MATCH(A1356 , RLC!A:A , 0) -> #N/A | F1356: {=INDEX(RLC!C:C ,E1356 , )} -> #N/A
A1357: менеджмента | B1357: 91 | C1357: 29.211495 | D1357: =D1356 + 1 -> 1356 | E1357: =MATCH(A1357 , RLC!A:A , 0) -> 2858 | F1357: {=INDEX(RLC!C:C ,E1357 , )} -> 39.860012
A1358: наша | B1358: 91 | C1358: 29.211495 | D1358: =D1357 + 1 -> 1357 | E1358: =MATCH(A1358 , RLC!A:A , 0) -> 551 | F1358: {=INDEX(RLC!C:C ,E1358 , )} -> 193.98539
A1359: поднятая | B1359: 91 | C1359: 29.211495 | D1359: =D1358 + 1 -> 1358 | E1359: =MATCH(A1359 , RLC!A:A , 0) -> #N/A | F1359: {=INDEX(RLC!C:C ,E1359 , )} -> #N/A
A1360: постепенно | B1360: 91 | C1360: 29.211495 | D1360: =D1359 + 1 -> 1359 | E1360: =MATCH(A1360 , RLC!A:A , 0) -> 2469 | F1360: {=INDEX(RLC!C:C ,E1360 , )} -> 46.503347
A1361: рублей | B1361: 91 | C1361: 29.211495 | D1361: =D1360 + 1 -> 1360 | E1361: =MATCH(A1361 , RLC!A:A , 0) -> 1697 | F1361: {=INDEX(RLC!C:C ,E1361 , )} -> 67.76202
A1362: сегодняшний | B1362: 91 | C1362: 29.211495 | D1362: =D1361 + 1 -> 1361 | E1362: =MATCH(A1362 , RLC!A:A , 0) -> 1873 | F1362: {=INDEX(RLC!C:C ,E1362 , )} -> 62.447352
... A1716: чехов | B1716: 73 | C1716: 23.433397 | D1716: =D1715 + 1 -> 1715 | E1716: =MATCH(A1716 , RLC!A:A , 0) -> #N/A | F1716: {=INDEX(RLC!C:C ,E1716 , )} -> #N/A
A1717: шапочка | B1717: 73 | C1717: 23.433397 | D1717: =D1716 + 1 -> 1716 | E1717: =MATCH(A1717 , RLC!A:A , 0) -> 3340 | F1717: {=INDEX(RLC!C:C ,E1717 , )} -> 34.545343 | G1717: =C1717>E1717 -> FALSE
A1718: широко | B1718: 73 | C1718: 23.433397 | D1718: =D1717 + 1 -> 1717 | E1718: =MATCH(A1718 , RLC!A:A , 0) -> 1585 | F1718: {=INDEX(RLC!C:C ,E1718 , )} -> 73.076688 | G1718: =C1718>E1718 -> FALSE
A1719: эмоций | B1719: 73 | C1719: 23.433397 | D1719: =D1718 + 1 -> 1718 | E1719: =MATCH(A1719 , RLC!A:A , 0) -> 6913 | F1719: {=INDEX(RLC!C:C ,E1719 , )} -> 15.944005
A1720: большие | B1720: 72 | C1720: 23.112392 | D1720: =D1719 + 1 -> 1719 | E1720: =MATCH(A1720 , RLC!A:A , 0) -> 837 | F1720: {=INDEX(RLC!C:C ,E1720 , )} -> 128.8807
A1721: большого | B1721: 72 | C1721: 23.112392 | D1721: =D1720 + 1 -> 1720 | E1721: =MATCH(A1721 , RLC!A:A , 0) -> 2651 | F1721: {=INDEX(RLC!C:C ,E1721 , )} -> 42.517346
A1722: ведет | B1722: 72 | C1722: 23.112392 | D1722: =D1721 + 1 -> 1721 | E1722: =MATCH(A1722 , RLC!A:A , 0) -> 3483 | F1722: {=INDEX(RLC!C:C ,E1722 , )} -> 31.888009
A1723: вниз | B1723: 72 | C1723: 23.112392 | D1723: =D1722 + 1 -> 1722 | E1723: =MATCH(A1723 , RLC!A:A , 0) -> 2832 | F1723: {=INDEX(RLC!C:C ,E1723 , )} -> 39.860012
A1724: вузов | B1724: 72 | C1724: 23.112392 | D1724: =D1723 + 1 -> 1723 | E1724: =MATCH(A1724 , RLC!A:A , 0) -> 6052 | F1724: {=INDEX(RLC!C:C ,E1724 , )} -> 17.272672
A1725: выражений | B1725: 72 | C1725: 23.112392 | D1725: =D1724 + 1 -> 1724 | E1725: =MATCH(A1725 , RLC!A:A , 0) -> 3786 | F1725: {=INDEX(RLC!C:C ,E1725 , )} -> 29.230675
A1726: гражданским | B1726: 72 | C1726: 23.112392 | D1726: =D1725 + 1 -> 1725 | E1726: =MATCH(A1726 , RLC!A:A , 0) -> #N/A | F1726: {=INDEX(RLC!C:C ,E1726 , )} -> #N/A
A1727: изучить | B1727: 72 | C1727: 23.112392 | D1727: =D1726 + 1 -> 1726 | E1727: =MATCH(A1727 , RLC!A:A , 0) -> 4372 | F1727: {=INDEX(RLC!C:C ,E1727 , )} -> 25.244674
...

Sheet RLC
A1: Слово | B1: Частота-RLC | C1: IPM-RLC | D1: Ранг-RLC | E1: Номер строки, на которой слово стоит в CorST
A2: и | B2: 28852 | C2: 38334.702 | D2: 1 | E2: =MATCH(A2 , CorST!A:A , 0) -> 3
A3: в | B3: 28595 | C3: 37993.234 | D3: =D2 + 1 -> 2 | E3: =MATCH(A3 , CorST!A:A , 0) -> 2
A4: что | B4: 12272 | C4: 16305.402 | D4: =D3 + 1 -> 3 | E4: =MATCH(A4 , CorST!A:A , 0) -> 7
A5: на | B5: 9984 | C5: 13265.412 | D5: =D4 + 1 -> 4 | E5: =MATCH(A5 , CorST!A:A , 0) -> 4
A6: не | B6: 9679 | C6: 12860.168 | D6: =D5 + 1 -> 5 | E6: =MATCH(A6 , CorST!A:A , 0) -> 5
A7: я | B7: 8489 | C7: 11279.055 | D7: =D6 + 1 -> 6 | E7: =MATCH(A7 , CorST!A:A , 0) -> 24
A8: с | B8: 6908 | C8: 9178.432 | D8: =D7 + 1 -> 7 | E8: =MATCH(A8 , CorST!A:A , 0) -> 6
A9: как | B9: 6227 | C9: 8273.6097 | D9: =D8 + 1 -> 8 | E9: =MATCH(A9 , CorST!A:A , 0) -> 8
A10: это | B10: 5389 | C10: 7160.1868 | D10: =D9 + 1 -> 9 | E10: =MATCH(A10 , CorST!A:A , 0) -> 15
A11: но | B11: 4307 | C11: 5722.569 | D11: =D10 + 1 -> 10 | E11: =MATCH(A11 , CorST!A:A , 0) -> 19
A12: он | B12: 4050 | C12: 5381.1016 | D12: =D11 + 1 -> 11 | E12: =MATCH(A12 , CorST!A:A , 0) -> 21
A13: о | B13: 3780 | C13: 5022.3615 | D13: =D12 + 1 -> 12 | E13: =MATCH(A13 , CorST!A:A , 0) -> 13
A14: для | B14: 3770 | C14: 5009.0748 | D14: =D13 + 1 -> 13 | E14: =MATCH(A14 , CorST!A:A , 0) -> 11
... A8127: японский | B8127: 10 | C8127: 13.286671 | D8127: =D8126 + 1 -> 8126 | E8127: =MATCH(A8127 , CorST!A:A , 0) -> 14067

Sheet merge
A1: Слово | B1: IPM-CorST | C1: IPM-RLC
A2: ячейки | B2: 11520.564 | C2: 37993.234
A3: ячеек | B3: 10090.806 | C3: 38334.702
A4: ясным | B4: 4241.1239 | C4: 13265.412
A5: ясность | B5: 3791.3953 | C5: 12860.168
A6: ясности | B6: 3647.5848 | C6: 9178.432
A7: ясно | B7: 3295.1208 | C7: 16305.402
A8: ясна | B8: 2374.1562 | C8: 8273.6097
A9: яркость | B9: 2179.6269 | C9: 4742.0127
A10: яркости | B10: 1901.6362 | C10: 3449.2197
A11: яркой | B11: 1814.3227 | C11: 5009.0748
A12: яркое | B12: 1808.5447 | C12: 4641.034
A13: ярко | B13: 1576.7787 | C13: 5022.3615
... A61: являться | B61: 349.57492 | C61: 482.30614
A62: являлся | B62: 347.9699
A63: являлось | B63: 345.40185 | C63: 987.19962
A64: являлись | B64: 343.47582 | C64: 180.69872
A65: являлась | B65: 343.47582 | C65: 196.64272
A66: является | B66: 340.90778 | C66: 1162.5837
A67: явлениями | B67: 340.90778 | C67: 749.36822
A68: явлениям | B68: 337.05571 | C68: 1194.4717
A69: явления | B69: 334.80867 | C69: 528.80949
A70: явлению | B70: 332.56164 | C70: 1353.9117
A71: явлений | B71: 332.24063 | C71: 3013.4169
A72: явлении | B72: 323.89449 | C72: 976.57029
A73: явлением | B73: 321.96846 | C73: 1037.689
A74: явление | B74: 321.64745 | C74: 1195.8003
... A114: эффектов | B114: 218.6047 | C114: 1909.2946
A115: эффективных | B115: 215.07365
A116: эффективным | B116: 213.14761 | C116: 310.90809
A117: эффективный | B117: 211.86359 | C117: 132.86671
A118: эффективность | B118: 211.54259 | C118: 1567.8271
A119: эффективности | B119: 209.29555 | C119: 389.29945
A120: эффективно | B120: 208.97454 | C120: 1307.4084
A121: эффективнее | B121: 207.36951 | C121: 572.6555
A122: эффективен | B122: 204.48047 | C122: 70.419354
A123: эффекта | B123: 203.19644 | C123: 1792.3719
A124: эффект | B124: 203.19644 | C124: 615.17285
A125: эту | B125: 202.55443 | C125: 2012.9306
A126: этот | B126: 202.23343 | C126: 659.01886
...
